Workbook

Sheet IDO E OUTROS DADOS
A1: DS | B1: BAIRRO | C1: CICLO 1 | D1: CICLO 2 | E1: CICLO 3 | F1: CICLO 4 | G1: CICLO 5 | H1: CICLO 6 | I1: CICLO 7 | J1: CICLO 8 | K1: CICLO 9 | L1: CICLO 10 | M1: CICLO 11 | N1: CICLO 12 | O1: CICLO 13 | P1: CICLO 14 | Q1: CICLO 15 | R1: CICLO 16 | S1: CICLO 17 | T1: CICLO 18 | U1: CICLO 19 | V1: CICLO 20 | W1: CICLO 21 | X1: CICLO 22 | Y1: CICLO 23 | Z1: CICLO 24 | AA1: CICLO 25 | AB1: CICLO 26 | AC1: FECHADO ANUAL | AD1: EXTRAVIADO ANUAL | AE1: RECUSADO ANUAL | AF1: DESOCUPADO ANUAL | AG1: RECUPERADA ANUAL | AH1: QTD. PALHETAS ANUAL | AI1: QTD. OVOS ANUAL
A2: I | B2: RECIFE | C2: ='[1]RECIFE ANTIGO'!$H$31 -> 153.375 | D2: ='[1]RECIFE ANTIGO'!K31 -> 122.6875 | E2: ='[1]RECIFE ANTIGO'!N31 -> 93.133333 | F2: ='[1]RECIFE ANTIGO'!Q31 -> 319.46667 | G2: ='[1]RECIFE ANTIGO'!T31 -> 244.2 | H2: ='[1]RECIFE ANTIGO'!W31 -> 128.23077 | I2: ='[1]RECIFE ANTIGO'!Z31 -> 217.4375 | J2: ='[1]RECIFE ANTIGO'!AC31 -> 207.70588 | K2: ='[1]RECIFE ANTIGO'!AF31 -> 75.941176 | L2: ='[1]RECIFE ANTIGO'!AI31 -> 168.875 | M2: ='[1]RECIFE ANTIGO'!AL31 -> 179.23529 | N2: ='[1]RECIFE ANTIGO'!AO31 -> 256.35294 | O2: ='[1]RECIFE ANTIGO'!AR31 -> 210.64706 | P2: ='[1]RECIFE ANTIGO'!AU31 -> 114.29412 | Q2: ='[1]RECIFE ANTIGO'!AX31 -> 151.625 | R2: ='[1]RECIFE ANTIGO'!BA31 -> 113 | S2: ='[1]RECIFE ANTIGO'!BD31 -> 111.05882 | T2: ='[1]RECIFE ANTIGO'!BG31 -> 166.5625 | U2: ='[1]RECIFE ANTIGO'!BJ31 -> 103.05882 | V2: ='[1]RECIFE ANTIGO'!BM31 -> #DIV/0! | W2: ='[1]RECIFE ANTIGO'!BP31 -> #DIV/0! | X2: ='[1]RECIFE ANTIGO'!BS31 -> #DIV/0! | Y2: ='[1]RECIFE ANTIGO'!BV31 -> #DIV/0! | Z2: ='[1]RECIFE ANTIGO'!BY31 -> #DIV/0! | AA2: ='[1]RECIFE ANTIGO'!CB31 -> #DIV/0! | AB2: ='[1]RECIFE ANTIGO'!CE31 -> #DIV/0! | AC2: ='[1]RECIFE ANTIGO'!B33 -> 1 | AD2: ='[1]RECIFE ANTIGO'!B34 -> 14 | AE2: ='[1]RECIFE ANTIGO'!B35 -> 0 | AF2: ='[1]RECIFE ANTIGO'!B36 -> 0 | AG2: ='[1]RECIFE ANTIGO'!B37 -> 1 | AH2: ='[1]RECIFE ANTIGO'!$B$39 -> 17 | AI2: ='[1]RECIFE ANTIGO'!$B$40 -> 50520
A3: I | B3: SANTO ANTÔNIO | C3: ='[1]SANTO ANTONIO'!H27 -> 330.6 | D3: ='[1]SANTO ANTONIO'!K27 -> 303.69231 | E3: ='[1]SANTO ANTONIO'!N27 -> 470.38462 | F3: ='[1]SANTO ANTONIO'!Q27 -> 394 | G3: ='[1]SANTO ANTONIO'!T27 -> 87.583333 | H3: ='[1]SANTO ANTONIO'!W27 -> 174.5 | I3: ='[1]SANTO ANTONIO'!Z27 -> 60.727273 | J3: ='[1]SANTO ANTONIO'!AC27 -> 157.25 | K3: ='[1]SANTO ANTONIO'!AF27 -> 83.230769 | L3: ='[1]SANTO ANTONIO'!AI27 -> 144.09091 | M3: ='[1]SANTO ANTONIO'!AL27 -> 126.77778 | N3: ='[1]SANTO ANTONIO'!AO27 -> 163.25 | O3: ='[1]SANTO ANTONIO'!AR27 -> 62.416667 | P3: ='[1]SANTO ANTONIO'!AU27 -> 126 | Q3: ='[1]SANTO ANTONIO'!AX27 -> 91.545455 | R3: ='[1]SANTO ANTONIO'!BA27 -> 93.307692 | S3: ='[1]SANTO ANTONIO'!BD27 -> 63.727273 | T3: ='[1]SANTO ANTONIO'!BG27 -> 87.2 | U3: ='[1]SANTO ANTONIO'!BJ27 -> 131.33333 | V3: ='[1]SANTO ANTONIO'!BM27 -> #DIV/0! | W3: ='[1]SANTO ANTONIO'!BP27 -> #DIV/0! | X3: ='[1]SANTO ANTONIO'!BS27 -> #DIV/0! | Y3: ='[1]SANTO ANTONIO'!BV27 -> #DIV/0! | Z3: ='[1]SANTO ANTONIO'!BY27 -> #DIV/0! | AA3: ='[1]SANTO ANTONIO'!CB27 -> #DIV/0! | AB3: ='[1]SANTO ANTONIO'!CE27 -> #DIV/0! | AC3: ='[1]SANTO ANTONIO'!B29 -> 4 | AD3: ='[1]SANTO ANTONIO'!B30 -> 3 | AE3: ='[1]SANTO ANTONIO'!B31 -> 0 | AF3: ='[1]SANTO ANTONIO'!B32 -> 0 | AG3: ='[1]SANTO ANTONIO'!B33 -> 1 | AH3: ='[1]SANTO ANTONIO'!B35 -> 13 | AI3: ='[1]SANTO ANTONIO'!B36 -> 35359
A4: I | B4: COELHOS | C4: =[1]COELHOS!$H$26 -> 129.36364 | D4: =[1]COELHOS!$K$26 -> 114.27273 | E4: =[1]COELHOS!N26 -> 263.36364 | F4: =[1]COELHOS!Q26 -> 410.91667 | G4: =[1]COELHOS!T26 -> 126.25 | H4: =[1]COELHOS!W26 -> 215.08333 | I4: =[1]COELHOS!Z26 -> 200.41667 | J4: =[1]COELHOS!AC26 -> 169.41667 | K4: =[1]COELHOS!AF26 -> 99.545455 | L4: =[1]COELHOS!AI26 -> 184.91667 | M4: =[1]COELHOS!AL26 -> 152.45455 | N4: =[1]COELHOS!AO26 -> 263.41667 | O4: =[1]COELHOS!AR26 -> 327.08333 | P4: =[1]COELHOS!AU26 -> 140.09091 | Q4: =[1]COELHOS!AX26 -> 192.33333 | R4: =[1]COELHOS!BA26 -> 206.75 | S4: =[1]COELHOS!BD26 -> 315.41667 | T4: =[1]COELHOS!BG26 -> 341.08333 | U4: =[1]COELHOS!BJ26 -> 174.66667 | V4: =[1]COELHOS!BM26 -> #DIV/0! | W4: =[1]COELHOS!BP26 -> #DIV/0! | X4: =[1]COELHOS!BS26 -> #DIV/0! | Y4: =[1]COELHOS!BV26 -> #DIV/0! | Z4: =[1]COELHOS!BY26 -> #DIV/0! | AA4: =[1]COELHOS!CB26 -> #DIV/0! | AB4: =[1]COELHOS!CE26 -> #DIV/0! | AC4: =[1]COELHOS!B28 -> 0 | AD4: =[1]COELHOS!B29 -> 6 | AE4: =[1]COELHOS!B30 -> 0 | AF4: =[1]COELHOS!B31 -> 0 | AG4: =[1]COELHOS!B32 -> 0 | AH4: =[1]COELHOS!B34 -> 12 | AI4: =[1]COELHOS!$B$35 -> 47423
A5: I | B5: PAISSANDU | C5: =[1]PAISSANDU!H20 -> 338.16667 | D5: =[1]PAISSANDU!K20 -> 276.16667 | E5: =[1]PAISSANDU!N20 -> 431.83333 | F5: =[1]PAISSANDU!Q20 -> 471.83333 | G5: =[1]PAISSANDU!T20 -> 473.16667 | H5: =[1]PAISSANDU!W20 -> 344.83333 | I5: =[1]PAISSANDU!Z20 -> 375.5 | J5: =[1]PAISSANDU!AC20 -> 569.66667 | K5: =[1]PAISSANDU!AF20 -> 293.16667 | L5: =[1]PAISSANDU!AI20 -> 466.16667 | M5: =[1]PAISSANDU!AL20 -> 417.33333 | N5: =[1]PAISSANDU!AO20 -> 339.5 | O5: =[1]PAISSANDU!AR20 -> 222.66667 | P5: =[1]PAISSANDU!AU20 -> 171.83333 | Q5: =[1]PAISSANDU!AX20 -> 138 | R5: =[1]PAISSANDU!BA20 -> 173.33333 | S5: =[1]PAISSANDU!BD20 -> 188.83333 | T5: =[1]PAISSANDU!BG20 -> 112.16667 | U5: =[1]PAISSANDU!BJ20 -> 158.4 | V5: =[1]PAISSANDU!BM20 -> #DIV/0! | W5: =[1]PAISSANDU!BP20 -> #DIV/0! | X5: =[1]PAISSANDU!BS20 -> #DIV/0! | Y5: =[1]PAISSANDU!BV20 -> #DIV/0! | Z5: =[1]PAISSANDU!BY20 -> #DIV/0! | AA5: =[1]PAISSANDU!CB20 -> #DIV/0! | AB5: =[1]PAISSANDU!CE20 -> #DIV/0! | AC5: =[1]PAISSANDU!B23 -> 0 | AD5: =[1]PAISSANDU!B24 -> 1 | AE5: =[1]PAISSANDU!B25 -> 0 | AF5: =[1]PAISSANDU!B26 -> 0 | AG5: =[1]PAISSANDU!B27 -> 0 | AH5: =[1]PAISSANDU!$B$29 -> 6 | AI5: =[1]PAISSANDU!$B$30 -> 35617
A6: I | B6: CABANGA | C6: =[1]CABANGA!H27 -> 75.4 | D6: =[1]CABANGA!K27 -> 109.23077 | E6: =[1]CABANGA!N27 -> 159.84615 | F6: =[1]CABANGA!Q27 -> 112.30769 | G6: =[1]CABANGA!T27 -> 190.66667 | H6: =[1]CABANGA!W27 -> 77.583333 | I6: =[1]CABANGA!Z27 -> 146.09091 | J6: =[1]CABANGA!AC27 -> 180.66667 | K6: =[1]CABANGA!AF27 -> 71 | L6: =[1]CABANGA!AI27 -> 214.66667 | M6: =[1]CABANGA!AL27 -> 264.61538 | N6: =[1]CABANGA!AO27 -> 196.33333 | O6: =[1]CABANGA!AR27 -> 80.181818 | P6: =[1]CABANGA!AU27 -> 50.75 | Q6: =[1]CABANGA!AX27 -> 296.84615 | R6: =[1]CABANGA!BA27 -> 106.15385 | S6: =[1]CABANGA!BD27 -> 90.538462 | T6: =[1]CABANGA!BG27 -> 147 | U6: =[1]CABANGA!BJ27 -> 85.230769 | V6: =[1]CABANGA!BM27 -> #DIV/0! | W6: =[1]CABANGA!BP27 -> #DIV/0! | X6: =[1]CABANGA!BS27 -> #DIV/0! | Y6: =[1]CABANGA!BV27 -> #DIV/0! | Z6: =[1]CABANGA!BY27 -> #DIV/0! | AA6: =[1]CABANGA!CB27 -> #DIV/0! | AB6: =[1]CABANGA!CE27 -> #DIV/0! | AC6: =[1]CABANGA!B30 -> 3 | AD6: =[1]CABANGA!B31 -> 10 | AE6: =[1]CABANGA!B32 -> 0 | AF6: =[1]CABANGA!B33 -> 0 | AG6: =[1]CABANGA!B34 -> 3 | AH6: =[1]CABANGA!$B$36 -> 13 | AI6: =[1]CABANGA!$B$37 -> 32856
A7: I | B7: SANTO AMARO | C7: ='[1]SANTO AMARO '!H98 -> 193.51807 | D7: ='[1]SANTO AMARO '!K98 -> 183.65432 | E7: ='[1]SANTO AMARO '!N98 -> 272.5119 | F7: ='[1]SANTO AMARO '!Q98 -> 422.36585 | G7: ='[1]SANTO AMARO '!T98 -> 260.52439 | H7: ='[1]SANTO AMARO '!W98 -> 326.78049 | I7: ='[1]SANTO AMARO '!Z98 -> 210.92683 | J7: ='[1]SANTO AMARO '!AC98 -> 182.10256 | K7: ='[1]SANTO AMARO '!AF98 -> 150.26506 | L7: ='[1]SANTO AMARO '!AI98 -> 277.22222 | M7: ='[1]SANTO AMARO '!AL98 -> 360.46988 | N7: ='[1]SANTO AMARO '!AO98 -> 298.73494 | O7: ='[1]SANTO AMARO '!AR98 -> 235.9759 | P7: ='[1]SANTO AMARO '!AU98 -> 197.11905 | Q7: ='[1]SANTO AMARO '!AX98 -> 234.24096 | R7: ='[1]SANTO AMARO '!BA98 -> 180.85542 | S7: ='[1]SANTO AMARO '!BD98 -> 180.40741 | T7: ='[1]SANTO AMARO '!BG98 -> 136.39241 | U7: ='[1]SANTO AMARO '!BJ98 -> 196.91566 | V7: ='[1]SANTO AMARO '!BM98 -> #DIV/0! | W7: ='[1]SANTO AMARO '!BP98 -> #DIV/0! | X7: ='[1]SANTO AMARO '!BS98 -> #DIV/0! | Y7: ='[1]SANTO AMARO '!BV98 -> #DIV/0! | Z7: ='[1]SANTO AMARO '!BY98 -> #DIV/0! | AA7: ='[1]SANTO AMARO '!CB98 -> #DIV/0! | AB7: ='[1]SANTO AMARO '!CE98 -> #DIV/0! | AC7: ='[1]SANTO AMARO '!B101 -> 10 | AD7: ='[1]SANTO AMARO '!B102 -> 12 | AE7: ='[1]SANTO AMARO '!B103 -> 0 | AF7: ='[1]SANTO AMARO '!B104 -> 0 | AG7: ='[1]SANTO AMARO '!B105 -> 5 | AH7: ='[1]SANTO AMARO '!$B$107 -> 84 | AI7: ='[1]SANTO AMARO '!$B$108 -> 370092
A8: I | B8: ILHA DO LEITE | C8: ='[1]ILHA DO LEITE'!H20 -> 296.25 | D8: ='[1]ILHA DO LEITE'!K20 -> 216.83333 | E8: ='[1]ILHA DO LEITE'!N20 -> 431.33333 | F8: ='[1]ILHA DO LEITE'!Q20 -> 267.33333 | G8: ='[1]ILHA DO LEITE'!T20 -> 472.83333 | H8: ='[1]ILHA DO LEITE'!W20 -> 413.83333 | I8: ='[1]ILHA DO LEITE'!Z20 -> 214 | J8: ='[1]ILHA DO LEITE'!AC20 -> 222.83333 | K8: ='[1]ILHA DO LEITE'!AF20 -> 78.333333 | L8: ='[1]ILHA DO LEITE'!AI20 -> 265 | M8: ='[1]ILHA DO LEITE'!AL20 -> 433.66667 | N8: ='[1]ILHA DO LEITE'!AO20 -> 255 | O8: ='[1]ILHA DO LEITE'!AR20 -> 177.8 | P8: ='[1]ILHA DO LEITE'!AU20 | Q8: ='[1]ILHA DO LEITE'!AX20 -> 190.16667 | R8: ='[1]ILHA DO LEITE'!BA20 -> 190.33333 | S8: ='[1]ILHA DO LEITE'!BD20 -> 201 | T8: ='[1]ILHA DO LEITE'!BG20 -> 104.83333 | U8: ='[1]ILHA DO LEITE'!BJ20 -> 243.16667 | V8: ='[1]ILHA DO LEITE'!BM20 -> #DIV/0! | W8: ='[1]ILHA DO LEITE'!BP20 -> #DIV/0! | X8: ='[1]ILHA DO LEITE'!BS20 -> #DIV/0! | Y8: ='[1]ILHA DO LEITE'!BV20 -> #DIV/0! | Z8: ='[1]ILHA DO LEITE'!BY20 -> #DIV/0! | AA8: ='[1]ILHA DO LEITE'!CB20 -> #DIV/0! | AB8: ='[1]ILHA DO LEITE'!CE20 -> #DIV/0! | AC8: ='[1]ILHA DO LEITE'!B22 -> 3 | AD8: ='[1]ILHA DO LEITE'!B23 -> 3 | AE8: ='[1]ILHA DO LEITE'!B24 -> 0 | AF8: ='[1]ILHA DO LEITE'!B25 -> 0 | AG8: ='[1]ILHA DO LEITE'!B26 -> 1 | AH8: ='[1]ILHA DO LEITE'!$B$28 -> 6 | AI8: ='[1]ILHA DO LEITE'!$B$29 -> 27909
A9: I | B9: SOLEDADE | C9: =[1]SOLEDADE!H23 -> 72 | D9: =[1]SOLEDADE!K23 -> 329.44444 | E9: =[1]SOLEDADE!N23 -> 423.88889 | F9: =[1]SOLEDADE!Q23 -> 355.77778 | G9: =[1]SOLEDADE!T23 -> 314 | H9: =[1]SOLEDADE!W23 -> 451.75 | I9: =[1]SOLEDADE!Z23 -> 186.44444 | J9: =[1]SOLEDADE!AC23 -> 211 | K9: =[1]SOLEDADE!AF23 -> 93.375 | L9: =[1]SOLEDADE!AI23 -> 198.11111 | M9: =[1]SOLEDADE!AL23 -> 183.44444 | N9: =[1]SOLEDADE!AO23 -> 251.55556 | O9: =[1]SOLEDADE!AR23 -> 235.44444 | P9: =[1]SOLEDADE!AU23 -> 109.66667 | Q9: =[1]SOLEDADE!AX23 -> 142.88889 | R9: =[1]SOLEDADE!BA23 -> 91.625 | S9: =[1]SOLEDADE!BD23 -> 110 | T9: =[1]SOLEDADE!BG23 -> 146.11111 | U9: =[1]SOLEDADE!BJ23 -> 145.77778 | V9: =[1]SOLEDADE!BM23 -> #DIV/0! | W9: =[1]SOLEDADE!BP23 -> #DIV/0! | X9: =[1]SOLEDADE!BS23 -> #DIV/0! | Y9: =[1]SOLEDADE!BV23 -> #DIV/0! | Z9: =[1]SOLEDADE!BY23 -> #DIV/0! | AA9: =[1]SOLEDADE!CB23 -> #DIV/0! | AB9: =[1]SOLEDADE!CE23 -> #DIV/0! | AC9: =[1]SOLEDADE!B26 -> 0 | AD9: =[1]SOLEDADE!B27 -> 2 | AE9: =[1]SOLEDADE!B28 -> 0 | AF9: =[1]SOLEDADE!B29 -> 0 | AG9: =[1]SOLEDADE!B30 -> 0 | AH9: =[1]SOLEDADE!$B$32 -> 9 | AI9: =[1]SOLEDADE!$B$33 -> 35614
A10: I | B10: SÃO JOSÉ | C10: ='[1]SÃO JOSÉ'!$H$61 -> 176.6087 | D10: ='[1]SÃO JOSÉ'!$K$61 -> 136.38636 | E10: ='[1]SÃO JOSÉ'!$N$61 -> 225.97436 | F10: ='[1]SÃO JOSÉ'!$Q$61 -> 158.65217 | G10: ='[1]SÃO JOSÉ'!$T$61 -> 145.37778 | H10: ='[1]SÃO JOSÉ'!$W$61 -> 214.80952 | I10: ='[1]SÃO JOSÉ'!$Z$61 -> 129.78571 | J10: ='[1]SÃO JOSÉ'!$AC$61 -> 185.46341 | K10: ='[1]SÃO JOSÉ'!$AF$61 -> 130.5 | L10: ='[1]SÃO JOSÉ'!$AI$61 -> 271.23913 | M10: ='[1]SÃO JOSÉ'!$AL$61 -> 285.69565 | N10: ='[1]SÃO JOSÉ'!$AO$61 -> 267.4 | O10: ='[1]SÃO JOSÉ'!$AR$61 -> 107.26087 | P10: ='[1]SÃO JOSÉ'!$AU$61 -> 190.02128 | Q10: ='[1]SÃO JOSÉ'!$AX$61 -> 178.13043 | R10: ='[1]SÃO JOSÉ'!$BA$61 -> 173.84091 | S10: ='[1]SÃO JOSÉ'!$BD$61 -> 173.77273 | T10: ='[1]SÃO JOSÉ'!$BG$61 -> 157.42222 | U10: ='[1]SÃO JOSÉ'!$BJ$61 -> 176.62222 | V10: ='[1]SÃO JOSÉ'!$BM$61 -> #DIV/0! | W10: ='[1]SÃO JOSÉ'!$BP$61 -> #DIV/0! | X10: ='[1]SÃO JOSÉ'!$BS$61 -> #DIV/0! | Y10: ='[1]SÃO JOSÉ'!$BV$61 -> #DIV/0! | Z10: ='[1]SÃO JOSÉ'!$BY$61 -> #DIV/0! | AA10: ='[1]SÃO JOSÉ'!$CB$61 -> #DIV/0! | AB10: ='[1]SÃO JOSÉ'!$CE$61 -> #DIV/0! | AC10: ='[1]SÃO JOSÉ'!B66 -> 14 | AD10: ='[1]SÃO JOSÉ'!B67 -> 18 | AE10: ='[1]SÃO JOSÉ'!B68 -> 0 | AF10: ='[1]SÃO JOSÉ'!B69 -> 0 | AG10: ='[1]SÃO JOSÉ'!B70 -> 11 | AH10: ='[1]SÃO JOSÉ'!$B$72 -> 47 | AI10: ='[1]SÃO JOSÉ'!$B$73 -> 154374
A11: I | B11: ILHA JOANA BEZERRA | C11: ='[1]ILHA JOANA BEZERRA'!H36 -> 104.66667 | D11: ='[1]ILHA JOANA BEZERRA'!K36 -> 225.9 | E11: ='[1]ILHA JOANA BEZERRA'!N36 -> 267.5 | F11: ='[1]ILHA JOANA BEZERRA'!Q36 -> 276.18182 | G11: ='[1]ILHA JOANA BEZERRA'!T36 -> 203.04545 | H11: ='[1]ILHA JOANA BEZERRA'!W36 -> 286.22727 | I11: ='[1]ILHA JOANA BEZERRA'!Z36 -> 272.38095 | J11: ='[1]ILHA JOANA BEZERRA'!AC36 -> 194.52381 | K11: ='[1]ILHA JOANA BEZERRA'!AF36 -> 125.63636 | L11: ='[1]ILHA JOANA BEZERRA'!AI36 -> 186.36364 | M11: ='[1]ILHA JOANA BEZERRA'!AL36 -> 242.72727 | N11: ='[1]ILHA JOANA BEZERRA'!AO36 -> 220.09091 | O11: ='[1]ILHA JOANA BEZERRA'!AR36 -> 111.95455 | P11: ='[1]ILHA JOANA BEZERRA'!AU36 -> 121.05 | Q11: ='[1]ILHA JOANA BEZERRA'!AX36 -> 168 | R11: ='[1]ILHA JOANA BEZERRA'!BA36 -> 232.73684 | S11: ='[1]ILHA JOANA BEZERRA'!BD36 -> 283.14286 | T11: ='[1]ILHA JOANA BEZERRA'!BG36 -> 251.31818 | U11: ='[1]ILHA JOANA BEZERRA'!BJ36 -> 175.59091 | V11: ='[1]ILHA JOANA BEZERRA'!BM36 -> #DIV/0! | W11: ='[1]ILHA JOANA BEZERRA'!BP36 -> #DIV/0! | X11: ='[1]ILHA JOANA BEZERRA'!BS36 -> #DIV/0! | Y11: ='[1]ILHA JOANA BEZERRA'!BV36 -> #DIV/0! | Z11: ='[1]ILHA JOANA BEZERRA'!BY36 -> #DIV/0! | AA11: ='[1]ILHA JOANA BEZERRA'!CB36 -> #DIV/0! | AB11: ='[1]ILHA JOANA BEZERRA'!CE36 -> #DIV/0! | AC11: ='[1]ILHA JOANA BEZERRA'!B41 -> 0 | AD11: ='[1]ILHA JOANA BEZERRA'!B42 -> 4 | AE11: ='[1]ILHA JOANA BEZERRA'!B43 -> 0 | AF11: ='[1]ILHA JOANA BEZERRA'!B44 -> 0 | AG11: ='[1]ILHA JOANA BEZERRA'!B45 -> 0 | AH11: ='[1]ILHA JOANA BEZERRA'!$B$47 -> 22 | AI11: ='[1]ILHA JOANA BEZERRA'!$B$48 -> 84632
A12: I | B12: BOA VISTA | C12: ='[1]BOA VISTA'!G59 -> 207.325 | D12: ='[1]BOA VISTA'!J59 -> 256.16279 | E12: ='[1]BOA VISTA'!M59 -> 334.95556 | F12: ='[1]BOA VISTA'!P59 -> 353.44444 | G12: ='[1]BOA VISTA'!S59 -> 190.11628 | H12: ='[1]BOA VISTA'!V59 -> 282.79487 | I12: ='[1]BOA VISTA'!Y59 -> 246.30952 | J12: ='[1]BOA VISTA'!AB59 -> 308.51163 | K12: ='[1]BOA VISTA'!AE59 -> 163.27273 | L12: ='[1]BOA VISTA'!AH59 -> 272.93182 | M12: ='[1]BOA VISTA'!AK59 -> 366.7907 | N12: ='[1]BOA VISTA'!AN59 -> 327.67442 | O12: ='[1]BOA VISTA'!AQ59 -> 228.72727 | P12: ='[1]BOA VISTA'!AT59 -> 203.11905 | Q12: ='[1]BOA VISTA'!AW59 -> 280.95556 | R12: ='[1]BOA VISTA'!AZ59 -> 219.26667 | S12: ='[1]BOA VISTA'!BC59 -> 267.95238 | T12: ='[1]BOA VISTA'!BF59 -> 222.20455 | U12: ='[1]BOA VISTA'!BI59 -> 214.59524 | V12: ='[1]BOA VISTA'!BL59 -> #DIV/0! | W12: ='[1]BOA VISTA'!BO59 -> #DIV/0! | X12: ='[1]BOA VISTA'!BR59 -> #DIV/0! | Y12: ='[1]BOA VISTA'!BU59 -> #DIV/0! | Z12: ='[1]BOA VISTA'!BX59 -> #DIV/0! | AA12: ='[1]BOA VISTA'!CA59 -> #DIV/0! | AB12: ='[1]BOA VISTA'!CD59 -> #DIV/0! | AC12: ='[1]BOA VISTA'!B63 -> 4 | AD12: ='[1]BOA VISTA'!B64 -> 14 | AE12: ='[1]BOA VISTA'!B65 -> 1 | AF12: ='[1]BOA VISTA'!B66 -> 0 | AG12: ='[1]BOA VISTA'!B67 -> 7 | AH12: ='[1]BOA VISTA'!$B$69 -> 45 | AI12: ='[1]BOA VISTA'!$B$70 -> 213305
A13: II | B13: ROSARINHO | C13: =[2]ROSARINHO!$H$21 -> 221.14286 | D13: =[2]ROSARINHO!K21 -> 315.14286 | E13: =[2]ROSARINHO!N21 -> 146.14286 | F13: =[2]ROSARINHO!Q21 -> 217.28571 | G13: =[2]ROSARINHO!T21 -> 298.85714 | H13: =[2]ROSARINHO!W21 -> 199.14286 | I13: =[2]ROSARINHO!Z21 -> 250.14286 | J13: =[2]ROSARINHO!AC21 -> 156.85714 | K13: =[2]ROSARINHO!AF21 -> 160.28571 | L13: =[2]ROSARINHO!AI21 -> 93 | M13: =[2]ROSARINHO!AL21 -> 329.5 | N13: =[2]ROSARINHO!AO21 -> 198.16667 | O13: =[2]ROSARINHO!AR21 -> 236.83333 | P13: =[2]ROSARINHO!AU21 -> 129.14286 | Q13: =[2]ROSARINHO!AX21 -> 196.4 | R13: =[2]ROSARINHO!BA21 -> 178.33333 | S13: =[2]ROSARINHO!BD21 -> 153.42857 | T13: =[2]ROSARINHO!BG21 -> 78.285714 | U13: =[2]ROSARINHO!BJ21 -> 219.57143 | V13: =[2]ROSARINHO!BM21 -> #DIV/0! | W13: =[2]ROSARINHO!BP21 -> #DIV/0! | X13: =[2]ROSARINHO!BS21 -> #DIV/0! | Y13: =[2]ROSARINHO!BV21 -> #DIV/0! | Z13: =[2]ROSARINHO!BY21 -> #DIV/0! | AA13: =[2]ROSARINHO!CB21 -> #DIV/0! | AB13: =[2]ROSARINHO!CE21 -> #DIV/0! | AC13: =[2]ROSARINHO!B23 -> 2 | AD13: =[2]ROSARINHO!B24 -> 2 | AE13: =[2]ROSARINHO!B25 -> 0 | AF13: =[2]ROSARINHO!B26 -> 1 | AG13: =[2]ROSARINHO!B27 -> 0 | AH13: =[2]ROSARINHO!$B$29 -> 7 | AI13: =[2]ROSARINHO!$B$30 -> 25108
A14: II | B14: LINHA DO TIRO | C14: ='[2]LINHA DO TIRO'!H42 -> 310.67857 | D14: ='[2]LINHA DO TIRO'!K42 -> 291.14286 | E14: ='[2]LINHA DO TIRO'!N42 -> 273.46429 | F14: ='[2]LINHA DO TIRO'!Q42 -> 354.40741 | G14: ='[2]LINHA DO TIRO'!T42 -> 430.48 | H14: ='[2]LINHA DO TIRO'!W42 -> 336.21429 | I14: ='[2]LINHA DO TIRO'!Z42 -> 300.35714 | J14: ='[2]LINHA DO TIRO'!AC42 -> 402.78571 | K14: ='[2]LINHA DO TIRO'!AF42 -> 222.82143 | L14: ='[2]LINHA DO TIRO'!AI42 -> 324 | M14: ='[2]LINHA DO TIRO'!AL42 -> 516.51852 | N14: ='[2]LINHA DO TIRO'!AO42 -> 238.88889 | O14: ='[2]LINHA DO TIRO'!AR42 -> 519 | P14: ='[2]LINHA DO TIRO'!AU42 -> 247.53571 | Q14: ='[2]LINHA DO TIRO'!AX42 -> 374.18519 | R14: ='[2]LINHA DO TIRO'!BA42 -> 432.59259 | S14: ='[2]LINHA DO TIRO'!BD42 -> 373.92857 | T14: ='[2]LINHA DO TIRO'!BG42 -> 161.07143 | U14: ='[2]LINHA DO TIRO'!BJ42 -> 295.10714 | V14: ='[2]LINHA DO TIRO'!BM42 -> #DIV/0! | W14: ='[2]LINHA DO TIRO'!BP42 -> #DIV/0! | X14: ='[2]LINHA DO TIRO'!BS42 -> #DIV/0! | Y14: ='[2]LINHA DO TIRO'!BV42 -> #DIV/0! | Z14: ='[2]LINHA DO TIRO'!BY42 -> #DIV/0! | AA14: ='[2]LINHA DO TIRO'!CB42 -> #DIV/0! | AB14: ='[2]LINHA DO TIRO'!CE42 -> #DIV/0! | AC14: ='[2]LINHA DO TIRO'!$B$46 -> 3 | AD14: ='[2]LINHA DO TIRO'!$B$46 -> 3 | AE14: ='[2]LINHA DO TIRO'!$B$46 -> 3 | AF14: ='[2]LINHA DO TIRO'!$B$46 -> 3 | AG14: =[2]ROSARINHO!$B$27 -> 0 | AH14: ='[2]LINHA DO TIRO'!$B$52 -> 28 | AI14: ='[2]LINHA DO TIRO'!$B$53 -> 175099
A15: II | B15: ENCRUZILHADA | C15: =[2]ENCRUZILHADA!H40 -> 276.2381 | D15: =[2]ENCRUZILHADA!K40 -> 228.53846 | E15: =[2]ENCRUZILHADA!N40 -> 484.5 | F15: =[2]ENCRUZILHADA!Q40 -> 255.42308 | G15: =[2]ENCRUZILHADA!T40 -> 331.76923 | H15: =[2]ENCRUZILHADA!W40 -> 322 | I15: =[2]ENCRUZILHADA!Z40 -> 203.96 | J15: =[2]ENCRUZILHADA!AC40 -> 271.44 | K15: =[2]ENCRUZILHADA!AF40 -> 254.56 | L15: =[2]ENCRUZILHADA!AI40 -> 281.22727 | M15: =[2]ENCRUZILHADA!AL40 -> 426.22727 | N15: =[2]ENCRUZILHADA!AO40 -> 456 | O15: =[2]ENCRUZILHADA!AR40 -> 343.91667 | P15: =[2]ENCRUZILHADA!AU40 -> 418.56522 | Q15: =[2]ENCRUZILHADA!AX40 -> 337.96 | R15: =[2]ENCRUZILHADA!BA40 -> 327.34615 | S15: =[2]ENCRUZILHADA!BD40 -> 222.68 | T15: =[2]ENCRUZILHADA!BG40 -> 124.29167 | U15: =[2]ENCRUZILHADA!BJ40 -> 146.7619 | V15: =[2]ENCRUZILHADA!BM40 -> #DIV/0! | W15: =[2]ENCRUZILHADA!BP40 -> #DIV/0! | X15: =[2]ENCRUZILHADA!BS40 -> #DIV/0! | Y15: =[2]ENCRUZILHADA!BV40 -> #DIV/0! | Z15: =[2]ENCRUZILHADA!BY40 -> #DIV/0! | AA15: =[2]ENCRUZILHADA!CB40 -> #DIV/0! | AB15: =[2]ENCRUZILHADA!CE40 -> #DIV/0! | AC15: =[2]ENCRUZILHADA!B43 -> 17 | AD15: =[2]ENCRUZILHADA!B44 -> 8 | AE15: =[2]ENCRUZILHADA!B45 -> 2 | AF15: =[2]ENCRUZILHADA!B46 -> 0 | AG15: =[2]ENCRUZILHADA!B47 -> 10 | AH15: =[2]ENCRUZILHADA!$B$49 -> 26 | AI15: =[2]ENCRUZILHADA!$B$50 -> 137140
A16: II | B16: DOIS UNIDOS | C16: ='[2]DOIS UNIDOS'!H82 -> 173.58333 | D16: ='[2]DOIS UNIDOS'!K82 -> 187.18033 | E16: ='[2]DOIS UNIDOS'!N82 -> 344.625 | F16: ='[2]DOIS UNIDOS'!Q82 -> 343.31148 | G16: ='[2]DOIS UNIDOS'!T82 -> 284.28814 | H16: ='[2]DOIS UNIDOS'!W82 -> 273.10909 | I16: ='[2]DOIS UNIDOS'!Z82 -> 312.21311 | J16: ='[2]DOIS UNIDOS'!AC82 -> 229.57143 | K16: ='[2]DOIS UNIDOS'!AF82 -> 166.51562 | L16: ='[2]DOIS UNIDOS'!AI82 -> 349.19355 | M16: ='[2]DOIS UNIDOS'!AL82 -> 303.8209 | N16: ='[2]DOIS UNIDOS'!AO82 -> 242.0625 | O16: ='[2]DOIS UNIDOS'!AR82 -> 272.30159 | P16: ='[2]DOIS UNIDOS'!AU82 -> 206.90625 | Q16: ='[2]DOIS UNIDOS'!AX82 -> 293.74194 | R16: ='[2]DOIS UNIDOS'!BA82 -> 214.56923 | S16: ='[2]DOIS UNIDOS'!BD82 -> 193.23077 | T16: ='[2]DOIS UNIDOS'!BG82 -> 216.50769 | U16: ='[2]DOIS UNIDOS'!BJ82 -> 243.87879 | V16: ='[2]DOIS UNIDOS'!BM82 -> #DIV/0! | W16: ='[2]DOIS UNIDOS'!BP82 -> #DIV/0! | X16: ='[2]DOIS UNIDOS'!BS82 -> #DIV/0! | Y16: ='[2]DOIS UNIDOS'!BV82 -> #DIV/0! | Z16: ='[2]DOIS UNIDOS'!BY82 -> #DIV/0! | AA16: ='[2]DOIS UNIDOS'!CB82 -> #DIV/0! | AB16: ='[2]DOIS UNIDOS'!CE82 -> #DIV/0! | AC16: ='[2]DOIS UNIDOS'!B86 -> 64 | AD16: ='[2]DOIS UNIDOS'!B87 -> 31 | AE16: ='[2]DOIS UNIDOS'!B88 -> 0 | AF16: ='[2]DOIS UNIDOS'!B89 -> 0 | AG16: ='[2]DOIS UNIDOS'!B90 -> 49 | AH16: ='[2]DOIS UNIDOS'!$B$92 -> 68 | AI16: ='[2]DOIS UNIDOS'!$B$93 -> 300816
A17: II | B17: ÁGUA FRIA | C17: ='[2]ÁGUA FRIA'!H78 -> 242.2069 | D17: ='[2]ÁGUA FRIA'!K78 -> 211.59322 | E17: ='[2]ÁGUA FRIA'!N78 -> 348.35593 | F17: ='[2]ÁGUA FRIA'!Q78 -> 440.85714 | G17: ='[2]ÁGUA FRIA'!T78 -> 365.90164 | H17: ='[2]ÁGUA FRIA'!W78 -> 309.3 | I17: ='[2]ÁGUA FRIA'!Z78 -> 501.5873 | J17: ='[2]ÁGUA FRIA'!AC78 -> 299 | K17: ='[2]ÁGUA FRIA'!AF78 -> 163.12903 | L17: ='[2]ÁGUA FRIA'!AI78 -> 299.19048 | M17: ='[2]ÁGUA FRIA'!AL78 -> 396.21311 | N17: ='[2]ÁGUA FRIA'!AO78 -> 291.32759 | O17: ='[2]ÁGUA FRIA'!AR78 -> 460.08333 | P17: ='[2]ÁGUA FRIA'!AU78 -> 316.32812 | Q17: ='[2]ÁGUA FRIA'!AX78 -> 386.74194 | R17: ='[2]ÁGUA FRIA'!BA78 -> 348.87931 | S17: ='[2]ÁGUA FRIA'!BD78 -> 381.6 | T17: ='[2]ÁGUA FRIA'!BG78 -> 384.55 | U17: ='[2]ÁGUA FRIA'!BJ78 -> 257.29825 | V17: ='[2]ÁGUA FRIA'!BM78 -> #DIV/0! | W17: ='[2]ÁGUA FRIA'!BP78 -> #DIV/0! | X17: ='[2]ÁGUA FRIA'!BS78 -> #DIV/0! | Y17: ='[2]ÁGUA FRIA'!BV78 -> #DIV/0! | Z17: ='[2]ÁGUA FRIA'!BY78 -> #DIV/0! | AA17: ='[2]ÁGUA FRIA'!CB78 -> #DIV/0! | AB17: ='[2]ÁGUA FRIA'!CE78 -> #DIV/0! | AC17: ='[2]ÁGUA FRIA'!B82 -> 33 | AD17: ='[2]ÁGUA FRIA'!B83 -> 30 | AE17: ='[2]ÁGUA FRIA'!B84 -> 0 | AF17: ='[2]ÁGUA FRIA'!B85 -> 0 | AG17: ='[2]ÁGUA FRIA'!B86 -> 30 | AH17: ='[2]ÁGUA FRIA'!$B$88 -> 64 | AI17: ='[2]ÁGUA FRIA'!$B$89 -> 387107
A18: II | B18: CAJUEIRO | C18: =[2]CAJUEIRO!H31 -> 119.76471 | D18: =[2]CAJUEIRO!K31 -> 126.26667 | E18: =[2]CAJUEIRO!N31 -> 270.70588 | F18: =[2]CAJUEIRO!Q31 -> 469.9375 | G18: =[2]CAJUEIRO!T31 -> 191.88235 | H18: =[2]CAJUEIRO!W31 -> 199.9375 | I18: =[2]CAJUEIRO!Z31 -> 291.875 | J18: =[2]CAJUEIRO!AC31 -> 458.93333 | K18: =[2]CAJUEIRO!AF31 -> 143.4 | L18: =[2]CAJUEIRO!AI31 -> 562.23529 | M18: =[2]CAJUEIRO!AL31 -> 421.93333 | N18: =[2]CAJUEIRO!AO31 -> 294.1875 | O18: =[2]CAJUEIRO!AR31 -> 304.35294 | P18: =[2]CAJUEIRO!AU31 -> 312.29412 | Q18: =[2]CAJUEIRO!AX31 -> 273.35294 | R18: =[2]CAJUEIRO!BA31 -> 236.05882 | S18: =[2]CAJUEIRO!BD31 -> 215.66667 | T18: =[2]CAJUEIRO!BG31 -> 249.6875 | U18: =[2]CAJUEIRO!BJ31 -> 251.5625 | V18: =[2]CAJUEIRO!BM31 -> #DIV/0! | W18: =[2]CAJUEIRO!BP31 -> #DIV/0! | X18: =[2]CAJUEIRO!BS31 -> #DIV/0! | Y18: =[2]CAJUEIRO!BV31 -> #DIV/0! | Z18: =[2]CAJUEIRO!BY31 -> #DIV/0! | AA18: =[2]CAJUEIRO!CB31 -> #DIV/0! | AB18: =[2]CAJUEIRO!CE31 -> #DIV/0! | AC18: =[2]CAJUEIRO!B34 -> 6 | AD18: =[2]CAJUEIRO!B35 -> 8 | AE18: =[2]CAJUEIRO!B36 -> 1 | AF18: =[2]CAJUEIRO!B37 -> 0 | AG18: =[2]CAJUEIRO!B38 -> 8 | AH18: =[2]CAJUEIRO!$B$40 -> 17 | AI18: =[2]CAJUEIRO!$B$41 -> 87209
A19: II | B19: BEBERIBE | C19: =[2]BEBERIBE!H31 -> 418.64706 | D19: =[2]BEBERIBE!K31 -> 242.94118 | E19: =[2]BEBERIBE!N31 -> 319.70588 | F19: =[2]BEBERIBE!Q31 -> 300.11765 | G19: =[2]BEBERIBE!T31 -> 330.47059 | H19: =[2]BEBERIBE!W31 -> 218.29412 | I19: =[2]BEBERIBE!Z31 -> 569.35294 | J19: =[2]BEBERIBE!AC31 -> 373.76471 | K19: =[2]BEBERIBE!AF31 -> 127.25 | L19: =[2]BEBERIBE!AI31 -> 156.58824 | M19: =[2]BEBERIBE!AL31 -> 197.29412 | N19: =[2]BEBERIBE!AO31 -> 413.29412 | O19: =[2]BEBERIBE!AR31 -> 315.82353 | P19: =[2]BEBERIBE!AU31 -> 339.5625 | Q19: =[2]BEBERIBE!AX31 -> 350.47059 | R19: =[2]BEBERIBE!BA31 -> 312.52941 | S19: =[2]BEBERIBE!BD31 -> 281.23529 | T19: =[2]BEBERIBE!BG31 -> 283.41176 | U19: =[2]BEBERIBE!BJ31 -> 179 | V19: =[2]BEBERIBE!BM31 -> #DIV/0! | W19: =[2]BEBERIBE!BP31 -> #DIV/0! | X19: =[2]BEBERIBE!BS31 -> #DIV/0! | Y19: =[2]BEBERIBE!BV31 -> #DIV/0! | Z19: =[2]BEBERIBE!BY31 -> #DIV/0! | AA19: =[2]BEBERIBE!CB31 -> #DIV/0! | AB19: =[2]BEBERIBE!CE31 -> #DIV/0! | AC19: =[2]BEBERIBE!B34 -> 0 | AD19: =[2]BEBERIBE!B35 -> 2 | AE19: =[2]BEBERIBE!B36 -> 0 | AF19: =[2]BEBERIBE!B37 -> 0 | AG19: =[2]BEBERIBE!B38 -> 1 | AH19: =[2]BEBERIBE!$B$40 -> 17 | AI19: =[2]BEBERIBE!$B$41 -> 96939
A20: II | B20: PORTO DA MADEIRA | C20: ='[2]PORTO DA MADEIRA'!H27 -> 245.75 | D20: ='[2]PORTO DA MADEIRA'!K27 -> 218.6 | E20: ='[2]PORTO DA MADEIRA'!N27 -> 372.69231 | F20: ='[2]PORTO DA MADEIRA'!Q27 -> 417.53846 | G20: ='[2]PORTO DA MADEIRA'!T27 -> 304.83333 | H20: ='[2]PORTO DA MADEIRA'!W27 -> 378.25 | I20: ='[2]PORTO DA MADEIRA'!Z27 -> 174.83333 | J20: ='[2]PORTO DA MADEIRA'!AC27 -> 219.69231 | K20: ='[2]PORTO DA MADEIRA'!AF27 -> 194.76923 | L20: ='[2]PORTO DA MADEIRA'!AI27 -> 276.8 | M20: ='[2]PORTO DA MADEIRA'!AL27 -> 274.90909 | N20: ='[2]PORTO DA MADEIRA'!AO27 -> 174.25 | O20: ='[2]PORTO DA MADEIRA'!AR27 -> 200.23077 | P20: ='[2]PORTO DA MADEIRA'!AU27 -> 164.38462 | Q20: ='[2]PORTO DA MADEIRA'!AX27 -> 238.69231 | R20: ='[2]PORTO DA MADEIRA'!BA27 -> 234.61538 | S20: ='[2]PORTO DA MADEIRA'!BD27 -> 243.83333 | T20: ='[2]PORTO DA MADEIRA'!BG27 -> 395.76923 | U20: ='[2]PORTO DA MADEIRA'!BJ27 -> 178.5 | V20: ='[2]PORTO DA MADEIRA'!BM27 -> #DIV/0! | W20: ='[2]PORTO DA MADEIRA'!BP27 -> #DIV/0! | X20: ='[2]PORTO DA MADEIRA'!BS27 -> #DIV/0! | Y20: ='[2]PORTO DA MADEIRA'!BV27 -> #DIV/0! | Z20: ='[2]PORTO DA MADEIRA'!BY27 -> #DIV/0! | AA20: ='[2]PORTO DA MADEIRA'!CB27 -> #DIV/0! | AB20: ='[2]PORTO DA MADEIRA'!CE27 -> #DIV/0! | AC20: ='[2]PORTO DA MADEIRA'!B30 -> 8 | AD20: ='[2]PORTO DA MADEIRA'!B31 -> 6 | AE20: ='[2]PORTO DA MADEIRA'!B32 -> 0 | AF20: ='[2]PORTO DA MADEIRA'!B33 -> 0 | AG20: ='[2]PORTO DA MADEIRA'!B34 -> 3 | AH20: ='[2]PORTO DA MADEIRA'!$B$36 -> 13 | AI20: ='[2]PORTO DA MADEIRA'!$B$37 -> 60080
A21: II | B21: FUNDÃO | C21: =[2]FUNDÃO!H30 -> 163.4375 | D21: =[2]FUNDÃO!K30 -> 220.1875 | E21: =[2]FUNDÃO!N30 -> 457.4375 | F21: =[2]FUNDÃO!Q30 -> 283.4 | G21: =[2]FUNDÃO!T30 -> 203.2 | H21: =[2]FUNDÃO!W30 -> 226.375 | I21: =[2]FUNDÃO!Z30 -> 537.8125 | J21: =[2]FUNDÃO!AC30 -> 262.9375 | K21: =[2]FUNDÃO!AF30 -> 134.5 | L21: =[2]FUNDÃO!AI30 -> 367 | M21: =[2]FUNDÃO!AL30 -> 434.5 | N21: =[2]FUNDÃO!AO30 -> 269.625 | O21: =[2]FUNDÃO!AR30 -> 292.3125 | P21: =[2]FUNDÃO!AU30 -> 277.46667 | Q21: =[2]FUNDÃO!AX30 -> 196.625 | R21: =[2]FUNDÃO!BA30 -> 281.9375 | S21: =[2]FUNDÃO!BD30 -> 244.4375 | T21: =[2]FUNDÃO!BG30 -> 306.75 | U21: =[2]FUNDÃO!BJ30 -> 166.3125 | V21: =[2]FUNDÃO!BM30 -> #DIV/0! | W21: =[2]FUNDÃO!BP30 -> #DIV/0! | X21: =[2]FUNDÃO!BS30 -> #DIV/0! | Y21: =[2]FUNDÃO!BV30 -> #DIV/0! | Z21: =[2]FUNDÃO!BY30 -> #DIV/0! | AA21: =[2]FUNDÃO!CB30 -> #DIV/0! | AB21: =[2]FUNDÃO!CE30 -> #DIV/0! | AC21: =[2]FUNDÃO!B33 -> 1 | AD21: =[2]FUNDÃO!B34 -> 2 | AE21: =[2]FUNDÃO!B35 -> 0 | AF21: =[2]FUNDÃO!B36 -> 0 | AG21: =[2]FUNDÃO!B37 -> 2 | AH21: =[2]FUNDÃO!$B$39 -> 16 | AI21: =[2]FUNDÃO!$B$40 -> 84456
A22: II | B22: HIPÓDROMO | C22: =[2]HIPODROMO!H23 -> 164.44444 | D22: =[2]HIPODROMO!K23 -> 212.75 | E22: =[2]HIPODROMO!N23 -> 241.375 | F22: =[2]HIPODROMO!Q23 -> 309.55556 | G22: =[2]HIPODROMO!T23 -> 176.55556 | H22: =[2]HIPODROMO!W23 -> 225.11111 | I22: =[2]HIPODROMO!Z23 -> 153.44444 | J22: =[2]HIPODROMO!AC23 -> 163.625 | K22: =[2]HIPODROMO!AF23 -> 240.22222 | L22: =[2]HIPODROMO!AI23 -> 238.55556 | M22: =[2]HIPODROMO!AL23 -> 362.88889 | N22: =[2]HIPODROMO!AO23 -> 109.33333 | O22: =[2]HIPODROMO!AR23 -> 208.88889 | P22: =[2]HIPODROMO!AU23 -> 187.44444 | Q22: =[2]HIPODROMO!AX23 -> 238 | R22: =[2]HIPODROMO!BA23 -> 193.22222 | S22: =[2]HIPODROMO!BD23 -> 282.44444 | T22: =[2]HIPODROMO!BG23 -> 129.11111 | U22: =[2]HIPODROMO!BJ23 -> 139.33333 | V22: =[2]HIPODROMO!BM23 -> #DIV/0! | W22: =[2]HIPODROMO!BP23 -> #DIV/0! | X22: =[2]HIPODROMO!BS23 -> #DIV/0! | Y22: =[2]HIPODROMO!BV23 -> #DIV/0! | Z22: =[2]HIPODROMO!BY23 -> #DIV/0! | AA22: =[2]HIPODROMO!CB23 -> #DIV/0! | AB22: =[2]HIPODROMO!CE23 -> #DIV/0! | AC22: =[2]HIPODROMO!B27 -> 0 | AD22: =[2]HIPODROMO!B28 -> 3 | AE22: =[2]HIPODROMO!B29 -> 0 | AF22: =[2]HIPODROMO!B30 -> 0 | AG22: =[2]HIPODROMO!B31 -> 3 | AH22: =[2]HIPODROMO!$B$33 -> 9 | AI22: =[2]HIPODROMO!$B$34 -> 35169
A23: II | B23: TORREÃO | C23: =[2]TORREÃO!H17 -> 115.33333 | D23: =[2]TORREÃO!K17 -> 159 | E23: =[2]TORREÃO!N17 -> 120.33333 | F23: =[2]TORREÃO!Q17 -> 76 | G23: =[2]TORREÃO!T17 -> 146.66667 | H23: =[2]TORREÃO!W17 -> 219.33333 | I23: =[2]TORREÃO!Z17 -> 91 | J23: =[2]TORREÃO!AC17 -> 83.333333 | K23: =[2]TORREÃO!AF17 -> 202 | L23: =[2]TORREÃO!AI17 -> 93.333333 | M23: =[2]TORREÃO!AL17 -> 142.66667 | N23: =[2]TORREÃO!AO17 -> 281.33333 | O23: =[2]TORREÃO!AR17 -> 213.33333 | P23: =[2]TORREÃO!AU17 -> 291 | Q23: =[2]TORREÃO!AX17 -> 167 | R23: =[2]TORREÃO!BA17 -> 49.333333 | S23: =[2]TORREÃO!BD17 -> 157.66667 | T23: =[2]TORREÃO!BG17 -> 107 | U23: =[2]TORREÃO!BJ17 -> 74 | V23: =[2]TORREÃO!BM17 -> #DIV/0! | W23: =[2]TORREÃO!BP17 -> #DIV/0! | X23: =[2]TORREÃO!BS17 -> #DIV/0! | Y23: =[2]TORREÃO!BV17 -> #DIV/0! | Z23: =[2]TORREÃO!BY17 -> #DIV/0! | AA23: =[2]TORREÃO!CB17 -> #DIV/0! | AB23: =[2]TORREÃO!CE17 -> #DIV/0! | AC23: =[2]TORREÃO!B20 -> 0 | AD23: =[2]TORREÃO!B21 -> 0 | AE23: =[2]TORREÃO!B22 -> 0 | AF23: =[2]TORREÃO!B23 -> 0 | AG23: =[2]TORREÃO!B24 -> 0 | AH23: =[2]TORREÃO!$B$26 -> 3 | AI23: =[2]TORREÃO!$B$27 -> 8369
A24: II | B24: BOMBA DO HEMETÉRIO | C24: ='[2]BOMBA DO HEMETERIO'!H35 -> 90.789474 | D24: ='[2]BOMBA DO HEMETERIO'!K35 -> 38.9375 | E24: ='[2]BOMBA DO HEMETERIO'!N35 -> 191 | F24: ='[2]BOMBA DO HEMETERIO'!Q35 -> 120.85 | G24: ='[2]BOMBA DO HEMETERIO'!T35 -> 113.95 | H24: ='[2]BOMBA DO HEMETERIO'!W35 -> 144.11111 | I24: ='[2]BOMBA DO HEMETERIO'!Z35 -> 149.6 | J24: ='[2]BOMBA DO HEMETERIO'!AC35 -> 224.35294 | K24: ='[2]BOMBA DO HEMETERIO'!AF35 -> 156.90476 | L24: ='[2]BOMBA DO HEMETERIO'!AI35 -> 280.66667 | M24: ='[2]BOMBA DO HEMETERIO'!AL35 -> 357.6 | N24: ='[2]BOMBA DO HEMETERIO'!AO35 -> 152.7619 | O24: ='[2]BOMBA DO HEMETERIO'!AR35 -> 257.52381 | P24: ='[2]BOMBA DO HEMETERIO'!AU35 -> 196.36842 | Q24: ='[2]BOMBA DO HEMETERIO'!AX35 -> 218.95238 | R24: ='[2]BOMBA DO HEMETERIO'!BA35 -> 139.05882 | S24: ='[2]BOMBA DO HEMETERIO'!BD35 -> 194.05263 | T24: ='[2]BOMBA DO HEMETERIO'!BG35 -> 253 | U24: ='[2]BOMBA DO HEMETERIO'!BJ35 -> 86.705882 | V24: ='[2]BOMBA DO HEMETERIO'!BM35 -> #DIV/0! | W24: ='[2]BOMBA DO HEMETERIO'!BP35 -> #DIV/0! | X24: ='[2]BOMBA DO HEMETERIO'!BS35 -> #DIV/0! | Y24: ='[2]BOMBA DO HEMETERIO'!BV35 -> #DIV/0! | Z24: ='[2]BOMBA DO HEMETERIO'!BY35 -> #DIV/0! | AA24: ='[2]BOMBA DO HEMETERIO'!CB35 -> #DIV/0! | AB24: ='[2]BOMBA DO HEMETERIO'!CE35 -> #DIV/0! | AC24: ='[2]BOMBA DO HEMETERIO'!B38 -> 11 | AD24: ='[2]BOMBA DO HEMETERIO'!B39 -> 11 | AE24: ='[2]BOMBA DO HEMETERIO'!B40 -> 1 | AF24: ='[2]BOMBA DO HEMETERIO'!B41 -> 0 | AG24: ='[2]BOMBA DO HEMETERIO'!B42 -> 14 | AH24: ='[2]BOMBA DO HEMETERIO'!$B$44 -> 21 | AI24: ='[2]BOMBA DO HEMETERIO'!$B$45 -> 65629
A25: II | B25: CAMPINA DO BARRETO | C25: ='[2]CAMPINA DO BARRETO'!H38 -> 196.54167 | D25: ='[2]CAMPINA DO BARRETO'!K38 -> 203.86957 | E25: ='[2]CAMPINA DO BARRETO'!N38 -> 517.63636 | F25: ='[2]CAMPINA DO BARRETO'!Q38 -> 542.04167 | G25: ='[2]CAMPINA DO BARRETO'!T38 -> 433.1 | H25: ='[2]CAMPINA DO BARRETO'!W38 -> 282.09091 | I25: ='[2]CAMPINA DO BARRETO'!Z38 -> 481.47826 | J25: ='[2]CAMPINA DO BARRETO'!AC38 -> 389.33333 | K25: ='[2]CAMPINA DO BARRETO'!AF38 -> 192.73913 | L25: ='[2]CAMPINA DO BARRETO'!AI38 -> 579.95652 | M25: ='[2]CAMPINA DO BARRETO'!AL38 -> 584.08333 | N25: ='[2]CAMPINA DO BARRETO'!AO38 -> 516.875 | O25: ='[2]CAMPINA DO BARRETO'!AR38 -> 205.36364 | P25: ='[2]CAMPINA DO BARRETO'!AU38 -> 299.41667 | Q25: ='[2]CAMPINA DO BARRETO'!AX38 -> 417.16667 | R25: ='[2]CAMPINA DO BARRETO'!BA38 -> 238.5 | S25: ='[2]CAMPINA DO BARRETO'!BD38 -> 494.95455 | T25: ='[2]CAMPINA DO BARRETO'!BG38 -> 301.2381 | U25: ='[2]CAMPINA DO BARRETO'!BJ38 -> 325.30435 | V25: ='[2]CAMPINA DO BARRETO'!BM38 -> #DIV/0! | W25: ='[2]CAMPINA DO BARRETO'!BP38 -> #DIV/0! | X25: ='[2]CAMPINA DO BARRETO'!BS38 -> #DIV/0! | Y25: ='[2]CAMPINA DO BARRETO'!BV38 -> #DIV/0! | Z25: ='[2]CAMPINA DO BARRETO'!BY38 -> #DIV/0! | AA25: ='[2]CAMPINA DO BARRETO'!CB38 -> #DIV/0! | AB25: ='[2]CAMPINA DO BARRETO'!CE38 -> #DIV/0! | AC25: ='[2]CAMPINA DO BARRETO'!B42 -> 14 | AD25: ='[2]CAMPINA DO BARRETO'!B43 -> 7 | AE25: ='[2]CAMPINA DO BARRETO'!B44 -> 0 | AF25: ='[2]CAMPINA DO BARRETO'!B45 -> 0 | AG25: ='[2]CAMPINA DO BARRETO'!B46 -> 14 | AH25: ='[2]CAMPINA DO BARRETO'!$B$48 -> 24 | AI25: ='[2]CAMPINA DO BARRETO'!$B$49 -> 164944
A26: II | B26: ARRUDA | C26: =[2]ARRUDA!H36 -> 165.90909 | D26: =[2]ARRUDA!K36 -> 151.33333 | E26: =[2]ARRUDA!N36 -> 258.47619 | F26: =[2]ARRUDA!Q36 -> 587.04762 | G26: =[2]ARRUDA!T36 -> 364.13636 | H26: =[2]ARRUDA!W36 -> 273.05 | I26: =[2]ARRUDA!Z36 -> 396.14286 | J26: =[2]ARRUDA!AC36 -> 240.63158 | K26: =[2]ARRUDA!AF36 -> 284.66667 | L26: =[2]ARRUDA!AI36 -> 301.95 | M26: =[2]ARRUDA!AL36 -> 399.1 | N26: =[2]ARRUDA!AO36 -> 301.95 | O26: =[2]ARRUDA!AR36 -> 299.36842 | P26: =[2]ARRUDA!AU36 -> 376 | Q26: =[2]ARRUDA!AX36 -> 354.31579 | R26: =[2]ARRUDA!BA36 -> 316.26316 | S26: =[2]ARRUDA!BD36 -> 387.75 | T26: =[2]ARRUDA!BG36 -> 265.15 | U26: =[2]ARRUDA!BJ36 -> 313.05 | V26: =[2]ARRUDA!BM36 -> #DIV/0! | W26: =[2]ARRUDA!BP36 -> #DIV/0! | X26: =[2]ARRUDA!BS36 -> #DIV/0! | Y26: =[2]ARRUDA!BV36 -> #DIV/0! | Z26: =[2]ARRUDA!BY36 -> #DIV/0! | AA26: =[2]ARRUDA!CB36 -> #DIV/0! | AB26: =[2]ARRUDA!CE36 -> #DIV/0! | AC26: =[2]ARRUDA!B39 -> 24 | AD26: =[2]ARRUDA!B40 -> 7 | AE26: =[2]ARRUDA!B41 -> 0 | AF26: =[2]ARRUDA!B42 -> 0 | AG26: =[2]ARRUDA!B43 -> 14 | AH26: =[2]ARRUDA!$B$45 -> 22 | AI26: =[2]ARRUDA!$B$46 -> 122253
A27: II | B27: PONTO DE PARADA | C27: ='[2]PONTO DE PARADA'!H18 -> 338.25 | D27: ='[2]PONTO DE PARADA'!K18 -> 209.25 | E27: ='[2]PONTO DE PARADA'!N18 -> 1244.75 | F27: ='[2]PONTO DE PARADA'!Q18 -> 348 | G27: ='[2]PONTO DE PARADA'!T18 -> 186.25 | H27: ='[2]PONTO DE PARADA'!W18 -> 372.75 | I27: ='[2]PONTO DE PARADA'!Z18 -> 323 | J27: ='[2]PONTO DE PARADA'!AC18 -> 418.33333 | K27: ='[2]PONTO DE PARADA'!AF18 -> 291.75 | L27: ='[2]PONTO DE PARADA'!$AI$18 -> 440 | M27: ='[2]PONTO DE PARADA'!AL18 -> 199.66667 | N27: ='[2]PONTO DE PARADA'!AO18 -> 379 | O27: ='[2]PONTO DE PARADA'!AR18 -> 803 | P27: ='[2]PONTO DE PARADA'!AU18 -> 284 | Q27: ='[2]PONTO DE PARADA'!AX18 -> 585.75 | R27: ='[2]PONTO DE PARADA'!BA18 -> 256.25 | S27: ='[2]PONTO DE PARADA'!BD18 -> 284.5 | T27: ='[2]PONTO DE PARADA'!BG18 -> 296 | U27: ='[2]PONTO DE PARADA'!BJ18 -> 221.75 | V27: ='[2]PONTO DE PARADA'!BM18 -> #DIV/0! | W27: ='[2]PONTO DE PARADA'!BP18 -> #DIV/0! | X27: ='[2]PONTO DE PARADA'!BS18 -> #DIV/0! | Y27: ='[2]PONTO DE PARADA'!BV18 -> #DIV/0! | Z27: ='[2]PONTO DE PARADA'!BY18 -> #DIV/0! | AA27: ='[2]PONTO DE PARADA'!CB18 -> #DIV/0! | AB27: ='[2]PONTO DE PARADA'!CE18 -> #DIV/0! | AC27: ='[2]PONTO DE PARADA'!B21 -> 1 | AD27: ='[2]PONTO DE PARADA'!B22 -> 1 | AE27: ='[2]PONTO DE PARADA'!B23 -> 1 | AF27: ='[2]PONTO DE PARADA'!B24 -> 0 | AG27: ='[2]PONTO DE PARADA'!B25 -> 3 | AH27: ='[2]PONTO DE PARADA'!$B$27 -> 4 | AI27: ='[2]PONTO DE PARADA'!$B$28 -> 28508
A28: II | B28: PEIXINHOS | C28: =[2]PEIXINHOS!H29 -> 221.84615 | D28: =[2]PEIXINHOS!K29 -> 192.46667 | E28: =[2]PEIXINHOS!N29 -> 352.5 | F28: =[2]PEIXINHOS!Q29 -> 691.84615 | G28: =[2]PEIXINHOS!T29 -> 329.07143 | H28: =[2]PEIXINHOS!W29 -> 274.73333 | I28: =[2]PEIXINHOS!Z29 -> 395.66667 | J28: =[2]PEIXINHOS!AC29 -> 250.8 | K28: =[2]PEIXINHOS!AF29 -> 266.93333 | L28: =[2]PEIXINHOS!AI29 -> 219.93333 | M28: =[2]PEIXINHOS!AL29 -> 362.93333 | N28: =[2]PEIXINHOS!AO29 -> 330.73333 | O28: =[2]PEIXINHOS!AR29 -> 307.92857 | P28: =[2]PEIXINHOS!AU29 -> 266.14286 | Q28: =[2]PEIXINHOS!AX29 -> 413.64286 | R28: =[2]PEIXINHOS!BA29 -> 239.26667 | S28: =[2]PEIXINHOS!BD29 -> 216.07143 | T28: =[2]PEIXINHOS!BG29 -> 212.14286 | U28: =[2]PEIXINHOS!BJ29 -> 183.33333 | V28: =[2]PEIXINHOS!BM29 -> #DIV/0! | W28: =[2]PEIXINHOS!BP29 -> #DIV/0! | X28: =[2]PEIXINHOS!BS29 -> #DIV/0! | Y28: =[2]PEIXINHOS!BV29 -> #DIV/0! | Z28: =[2]PEIXINHOS!BY29 -> #DIV/0! | AA28: =[2]PEIXINHOS!CB29 -> #DIV/0! | AB28: =[2]PEIXINHOS!CE29 -> #DIV/0! | AC28: =[2]PEIXINHOS!B32 -> 8 | AD28: =[2]PEIXINHOS!B33 -> 3 | AE28: =[2]PEIXINHOS!B34 -> 0 | AF28: =[2]PEIXINHOS!B35 -> 0 | AG28: =[2]PEIXINHOS!B36 -> 5 | AH28: =[2]PEIXINHOS!$B$38 -> 15 | AI28: =[2]PEIXINHOS!$B$39 -> 81445
A29: II | B29: ALTO SANTA TEREZINHA | C29: ='[2]ALTO SANTA TEREZINHA'!H27 -> 254.09091 | D29: ='[2]ALTO SANTA TEREZINHA'!K27 -> 112.72727 | E29: ='[2]ALTO SANTA TEREZINHA'!N27 -> 277.33333 | F29: ='[2]ALTO SANTA TEREZINHA'!Q27 -> 381.75 | G29: ='[2]ALTO SANTA TEREZINHA'!T27 -> 351.81818 | H29: ='[2]ALTO SANTA TEREZINHA'!W27 -> 789.91667 | I29: ='[2]ALTO SANTA TEREZINHA'!Z27 -> 496.83333 | J29: ='[2]ALTO SANTA TEREZINHA'!AC27 -> 247.11111 | K29: ='[2]ALTO SANTA TEREZINHA'!AF27 -> 114.18182 | L29: ='[2]ALTO SANTA TEREZINHA'!AI27 -> 228.6 | M29: ='[2]ALTO SANTA TEREZINHA'!AL27 -> 315.09091 | N29: ='[2]ALTO SANTA TEREZINHA'!AO27 -> 449.45455 | O29: ='[2]ALTO SANTA TEREZINHA'!AR27 -> 297.25 | P29: ='[2]ALTO SANTA TEREZINHA'!AU27 -> 358.92308 | Q29: ='[2]ALTO SANTA TEREZINHA'!AX27 -> 231.46154 | R29: ='[2]ALTO SANTA TEREZINHA'!BA27 -> 216.81818 | S29: ='[2]ALTO SANTA TEREZINHA'!BD27 -> 188.76923 | T29: ='[2]ALTO SANTA TEREZINHA'!BG27 -> 201.45455 | U29: ='[2]ALTO SANTA TEREZINHA'!BJ27 -> 100.3 | V29: ='[2]ALTO SANTA TEREZINHA'!BM27 -> #DIV/0! | W29: ='[2]ALTO SANTA TEREZINHA'!BP27 -> #DIV/0! | X29: ='[2]ALTO SANTA TEREZINHA'!BS27 -> #DIV/0! | Y29: ='[2]ALTO SANTA TEREZINHA'!BV27 -> #DIV/0! | Z29: ='[2]ALTO SANTA TEREZINHA'!BY27 -> #DIV/0! | AA29: ='[2]ALTO SANTA TEREZINHA'!CB27 -> #DIV/0! | AB29: ='[2]ALTO SANTA TEREZINHA'!CE27 -> #DIV/0! | AC29: ='[2]ALTO SANTA TEREZINHA'!B30 -> 16 | AD29: ='[2]ALTO SANTA TEREZINHA'!B31 -> 11 | AE29: ='[2]ALTO SANTA TEREZINHA'!B32 -> 0 | AF29: ='[2]ALTO SANTA TEREZINHA'!B33 -> 0 | AG29: ='[2]ALTO SANTA TEREZINHA'!B34 -> 7 | AH29: ='[2]ALTO SANTA TEREZINHA'!$B$36 -> 13 | AI29: ='[2]ALTO SANTA TEREZINHA'!$B$37 -> 64731
A30: II | B30: CAMPO GRANDE | C30: ='[2]CAMPO GRANDE'!H67 -> 206.02326 | D30: ='[2]CAMPO GRANDE'!K67 -> 302.34884 | E30: ='[2]CAMPO GRANDE'!N67 -> 575.67391 | F30: ='[2]CAMPO GRANDE'!Q67 -> 417.5 | G30: ='[2]CAMPO GRANDE'!T67 -> 431.25532 | H30: ='[2]CAMPO GRANDE'!W67 -> 483.62745 | I30: ='[2]CAMPO GRANDE'!Z67 -> 435.87755 | J30: ='[2]CAMPO GRANDE'!AC67 -> 274.89796 | K30: ='[2]CAMPO GRANDE'!AF67 -> 281.90196 | L30: ='[2]CAMPO GRANDE'!AI67 -> 586.60377 | M30: ='[2]CAMPO GRANDE'!AL67 -> 394.94231 | N30: ='[2]CAMPO GRANDE'!AO67 -> 507.1 | O30: ='[2]CAMPO GRANDE'!AR67 -> 327.40816 | P30: ='[2]CAMPO GRANDE'!AU67 -> 448.14 | Q30: ='[2]CAMPO GRANDE'!AX67 -> 474.91837 | R30: ='[2]CAMPO GRANDE'!BA67 -> 203.55102 | S30: ='[2]CAMPO GRANDE'!BD67 -> 199.69231 | T30: ='[2]CAMPO GRANDE'!BG67 -> 279.26667 | U30: ='[2]CAMPO GRANDE'!BJ67 -> 257.15217 | V30: ='[2]CAMPO GRANDE'!BM67 -> #DIV/0! | W30: ='[2]CAMPO GRANDE'!BP67 -> #DIV/0! | X30: ='[2]CAMPO GRANDE'!BS67 -> #DIV/0! | Y30: ='[2]CAMPO GRANDE'!BV67 -> #DIV/0! | Z30: ='[2]CAMPO GRANDE'!BY67 -> #DIV/0! | AA30: ='[2]CAMPO GRANDE'!CB67 -> #DIV/0! | AB30: ='[2]CAMPO GRANDE'!CE67 -> #DIV/0! | AC30: ='[2]CAMPO GRANDE'!B71 -> 48 | AD30: ='[2]CAMPO GRANDE'!B72 -> 27 | AE30: ='[2]CAMPO GRANDE'!B73 -> 0 | AF30: ='[2]CAMPO GRANDE'!B74 -> 0 | AG30: ='[2]CAMPO GRANDE'!B75 -> 28 | AH30: ='[2]CAMPO GRANDE'!$B$77 -> 53 | AI30: ='[2]CAMPO GRANDE'!$B$78 -> 345142
A31: III | B31: APIPUCOS | C31: =[3]APIPUCOS!H38 -> 185.38889 | D31: =[3]APIPUCOS!K38 -> 271.04545 | E31: =[3]APIPUCOS!N38 -> 399.28571 | F31: =[3]APIPUCOS!Q38 -> 742 | G31: =[3]APIPUCOS!T38 -> 193.3913 | H31: =[3]APIPUCOS!W38 -> 314.28571 | I31: =[3]APIPUCOS!Z38 -> 163.61905 | J31: =[3]APIPUCOS!AC38 -> 196.18182 | K31: =[3]APIPUCOS!AF38 -> 131.81818 | L31: =[3]APIPUCOS!AI38 -> 174.5 | M31: =[3]APIPUCOS!AL38 -> 407.6087 | N31: =[3]APIPUCOS!AO38 -> 210.63636 | O31: =[3]APIPUCOS!AR38 -> 173.57143 | P31: =[3]APIPUCOS!AU38 -> 166.04762 | Q31: =[3]APIPUCOS!AX38 -> 293.42857 | R31: =[3]APIPUCOS!BA38 -> 270.04762 | S31: =[3]APIPUCOS!BD38 -> 213.09524 | T31: =[3]APIPUCOS!BG38 -> 246.04348 | U31: =[3]APIPUCOS!BJ38 -> 183.04762 | V31: =[3]APIPUCOS!BM38 -> #DIV/0! | W31: =[3]APIPUCOS!BP38 -> #DIV/0! | X31: =[3]APIPUCOS!BS38 -> #DIV/0! | Y31: =[3]APIPUCOS!BV38 -> #DIV/0! | Z31: =[3]APIPUCOS!BY38 -> #DIV/0! | AA31: =[3]APIPUCOS!CB38 -> #DIV/0! | AB31: =[3]APIPUCOS!CE38 -> #DIV/0! | AC31: =[3]APIPUCOS!B42 -> 21 | AD31: =[3]APIPUCOS!B43 -> 24 | AE31: =[3]APIPUCOS!B44 -> 0 | AF31: =[3]APIPUCOS!B45 -> 0 | AG31: =[3]APIPUCOS!B46 -> 14 | AH31: =[3]APIPUCOS!$B$48 -> 24 | AI31: =[3]APIPUCOS!$B$49 -> 105758
A32: III | B32: DOIS IRMÃOS | C32: ='[3]DOIS IRMÃOS'!H51 -> 107.75676 | D32: ='[3]DOIS IRMÃOS'!K51 -> 299.27027 | E32: ='[3]DOIS IRMÃOS'!N51 -> 307.27778 | F32: ='[3]DOIS IRMÃOS'!Q51 -> 291.27027 | G32: ='[3]DOIS IRMÃOS'!T51 -> 197.75676 | H32: ='[3]DOIS IRMÃOS'!W51 -> 289.2973 | I32: ='[3]DOIS IRMÃOS'!Z51 -> 223.41667 | J32: ='[3]DOIS IRMÃOS'!AC51 -> 114.30556 | K32: ='[3]DOIS IRMÃOS'!AF51 -> 129.51351 | L32: ='[3]DOIS IRMÃOS'!AI51 -> 270.25 | M32: ='[3]DOIS IRMÃOS'!AL51 -> 161.51351 | N32: ='[3]DOIS IRMÃOS'!AO51 -> 151.83333 | O32: ='[3]DOIS IRMÃOS'!AR51 -> 218.75 | P32: ='[3]DOIS IRMÃOS'!AU51 -> 146.18919 | Q32: ='[3]DOIS IRMÃOS'!AX51 -> 155.02703 | R32: ='[3]DOIS IRMÃOS'!BA51 -> 138.27027 | S32: ='[3]DOIS IRMÃOS'!BD51 -> 132.37143 | T32: ='[3]DOIS IRMÃOS'!BG51 -> 106.25 | U32: ='[3]DOIS IRMÃOS'!BJ51 -> 225.05714 | V32: ='[3]DOIS IRMÃOS'!BM51 -> #DIV/0! | W32: ='[3]DOIS IRMÃOS'!BP51 -> #DIV/0! | X32: ='[3]DOIS IRMÃOS'!BS51 -> #DIV/0! | Y32: ='[3]DOIS IRMÃOS'!BV51 -> #DIV/0! | Z32: ='[3]DOIS IRMÃOS'!BY51 -> #DIV/0! | AA32: ='[3]DOIS IRMÃOS'!CB51 -> #DIV/0! | AB32: ='[3]DOIS IRMÃOS'!CE51 -> #DIV/0! | AC32: ='[3]DOIS IRMÃOS'!B55 -> 1 | AD32: ='[3]DOIS IRMÃOS'!B56 -> 3 | AE32: ='[3]DOIS IRMÃOS'!B57 -> 1 | AF32: ='[3]DOIS IRMÃOS'!B58 -> 0 | AG32: ='[3]DOIS IRMÃOS'!B59 -> 0 | AH32: ='[3]DOIS IRMÃOS'!$B$61 -> 37 | AI32: ='[3]DOIS IRMÃOS'!$B$62 -> 133087
A33: III | B33: MONTEIRO | C33: =[3]MONTEIRO!H31 -> 189.52941 | D33: =[3]MONTEIRO!K31 -> 248.35294 | E33: =[3]MONTEIRO!N31 -> 537.58824 | F33: =[3]MONTEIRO!Q31 -> 718.11765 | G33: =[3]MONTEIRO!T31 -> 302.76471 | H33: =[3]MONTEIRO!W31 -> 631.58824 | I33: =[3]MONTEIRO!Z31 -> 562.47059 | J33: =[3]MONTEIRO!AC31 -> 724.05882 | K33: =[3]MONTEIRO!AF31 -> 342.3125 | L33: =[3]MONTEIRO!AI31 -> 350.82353 | M33: =[3]MONTEIRO!AL31 -> 554.52941 | N33: =[3]MONTEIRO!AO31 -> 162.05882 | O33: =[3]MONTEIRO!AR31 -> 309.29412 | P33: =[3]MONTEIRO!AU31 -> 196.6 | Q33: =[3]MONTEIRO!AX31 -> 419.6 | R33: =[3]MONTEIRO!BA31 -> 341.0625 | S33: =[3]MONTEIRO!BD31 -> 391 | T33: =[3]MONTEIRO!BG31 -> 321.8125 | U33: =[3]MONTEIRO!BJ31 -> 400.5 | V33: =[3]MONTEIRO!BM31 -> #DIV/0! | W33: =[3]MONTEIRO!BP31 -> #DIV/0! | X33: =[3]MONTEIRO!BS31 -> #DIV/0! | Y33: =[3]MONTEIRO!BV31 -> #DIV/0! | Z33: =[3]MONTEIRO!BY31 -> #DIV/0! | AA33: =[3]MONTEIRO!CB31 -> #DIV/0! | AB33: =[3]MONTEIRO!CE31 -> #DIV/0! | AC33: =[3]MONTEIRO!B34 -> 5 | AD33: =[3]MONTEIRO!B35 -> 4 | AE33: =[3]MONTEIRO!B36 -> 0 | AF33: =[3]MONTEIRO!B37 -> 0 | AG33: =[3]MONTEIRO!B38 -> 1 | AH33: =[3]MONTEIRO!$B$40 -> 17 | AI33: =[3]MONTEIRO!$B$41 -> 127940
A34: III | B34: CASA AMARELA | C34: ='[3]CASA AMARELA'!H66 -> 209.12821 | D34: ='[3]CASA AMARELA'!K66 -> 309.84 | E34: ='[3]CASA AMARELA'!N66 -> 278.58824 | F34: ='[3]CASA AMARELA'!Q66 -> 440.32 | G34: ='[3]CASA AMARELA'!T66 -> 274.24 | H34: ='[3]CASA AMARELA'!W66 -> 417.32609 | I34: ='[3]CASA AMARELA'!Z66 -> 250.82 | J34: ='[3]CASA AMARELA'!AC66 -> 312.86957 | K34: ='[3]CASA AMARELA'!AF66 -> 192.89583 | L34: ='[3]CASA AMARELA'!AI66 -> 292.72917 | M34: ='[3]CASA AMARELA'!AL66 -> 331.57447 | N34: ='[3]CASA AMARELA'!AO66 -> 194.11628 | O34: ='[3]CASA AMARELA'!AR66 -> 233.89583 | P34: ='[3]CASA AMARELA'!AU66 -> 153.30612 | Q34: ='[3]CASA AMARELA'!AX66 -> 232.8125 | R34: ='[3]CASA AMARELA'!BA66 -> 240.12245 | S34: ='[3]CASA AMARELA'!BD66 -> 238.55319 | T34: ='[3]CASA AMARELA'!BG66 -> 137.89744 | U34: ='[3]CASA AMARELA'!BJ66 -> 183.79167 | V34: ='[3]CASA AMARELA'!BM66 -> #DIV/0! | W34: ='[3]CASA AMARELA'!BP66 -> #DIV/0! | X34: ='[3]CASA AMARELA'!BS66 -> #DIV/0! | Y34: ='[3]CASA AMARELA'!BV66 -> #DIV/0! | Z34: ='[3]CASA AMARELA'!BY66 -> #DIV/0! | AA34: ='[3]CASA AMARELA'!CB66 -> #DIV/0! | AB34: ='[3]CASA AMARELA'!CE66 -> #DIV/0! | AC34: ='[3]CASA AMARELA'!B70 -> 57 | AD34: ='[3]CASA AMARELA'!B71 -> 30 | AE34: ='[3]CASA AMARELA'!B72 -> 1 | AF34: ='[3]CASA AMARELA'!B73 -> 0 | AG34: ='[3]CASA AMARELA'!B74 -> 54 | AH34: ='[3]CASA AMARELA'!$B$76 -> 52 | AI34: ='[3]CASA AMARELA'!$B$77 -> 234047
A35: III | B35: ALTO DO MANDU | C35: ='[3]ALTO DO MANDU'!H23 -> 169 | D35: ='[3]ALTO DO MANDU'!K23 -> 133.11111 | E35: ='[3]ALTO DO MANDU'!N23 -> 147.88889 | F35: ='[3]ALTO DO MANDU'!Q23 -> 169.11111 | G35: ='[3]ALTO DO MANDU'!T23 -> 73.714286 | H35: ='[3]ALTO DO MANDU'!W23 -> 179.75 | I35: ='[3]ALTO DO MANDU'!Z23 -> 175.28571 | J35: ='[3]ALTO DO MANDU'!AC23 -> 94.125 | K35: ='[3]ALTO DO MANDU'!AF23 -> 16.833333 | L35: ='[3]ALTO DO MANDU'!AI23 -> 129.28571 | M35: ='[3]ALTO DO MANDU'!AL23 -> 159.75 | N35: ='[3]ALTO DO MANDU'!AO23 -> 257.875 | O35: ='[3]ALTO DO MANDU'!AR23 -> 336.44444 | P35: ='[3]ALTO DO MANDU'!AU23 -> 83.285714 | Q35: ='[3]ALTO DO MANDU'!AX23 -> 262.88889 | R35: ='[3]ALTO DO MANDU'!BA23 -> 139.25 | S35: ='[3]ALTO DO MANDU'!BD23 -> 104.75 | T35: ='[3]ALTO DO MANDU'!BG23 -> 82.333333 | U35: ='[3]ALTO DO MANDU'!BJ23 -> 243.125 | V35: ='[3]ALTO DO MANDU'!BM23 -> #DIV/0! | W35: ='[3]ALTO DO MANDU'!BP23 -> #DIV/0! | X35: ='[3]ALTO DO MANDU'!BS23 -> #DIV/0! | Y35: ='[3]ALTO DO MANDU'!BV23 -> #DIV/0! | Z35: ='[3]ALTO DO MANDU'!BY23 -> #DIV/0! | AA35: ='[3]ALTO DO MANDU'!CB23 -> #DIV/0! | AB35: ='[3]ALTO DO MANDU'!CE23 -> #DIV/0! | AC35: ='[3]ALTO DO MANDU'!B26 -> 11 | AD35: ='[3]ALTO DO MANDU'!B27 -> 4 | AE35: ='[3]ALTO DO MANDU'!B28 -> 1 | AF35: ='[3]ALTO DO MANDU'!B29 -> 0 | AG35: ='[3]ALTO DO MANDU'!B30 -> 12 | AH35: ='[3]ALTO DO MANDU'!$B$32 -> 9 | AI35: ='[3]ALTO DO MANDU'!$B$33 -> 24221
A36: III | B36: CASA FORTE | C36: ='[3]CASA FORTE'!H28 -> 160.58333 | D36: ='[3]CASA FORTE'!K28 -> 180.14286 | E36: ='[3]CASA FORTE'!N28 -> 265.5 | F36: ='[3]CASA FORTE'!Q28 -> 280.64286 | G36: ='[3]CASA FORTE'!T28 -> 170.07143 | H36: ='[3]CASA FORTE'!W28 -> 193.30769 | I36: ='[3]CASA FORTE'!Z28 -> 326.5 | J36: ='[3]CASA FORTE'!AC28 -> 203.71429 | K36: ='[3]CASA FORTE'!AF28 -> 55.642857 | L36: ='[3]CASA FORTE'!AI28 -> 260.78571 | M36: ='[3]CASA FORTE'!AL28 -> 246.35714 | N36: ='[3]CASA FORTE'!AO28 -> 181.92857 | O36: ='[3]CASA FORTE'!AR28 -> 280.38462 | P36: ='[3]CASA FORTE'!AU28 -> 200 | Q36: ='[3]CASA FORTE'!AX28 -> 138.71429 | R36: ='[3]CASA FORTE'!BA28 -> 417.14286 | S36: ='[3]CASA FORTE'!BD28 -> 164.64286 | T36: ='[3]CASA FORTE'!BG28 -> 149.35714 | U36: ='[3]CASA FORTE'!BJ28 -> 143 | V36: ='[3]CASA FORTE'!BM28 -> #DIV/0! | W36: ='[3]CASA FORTE'!BP28 -> #DIV/0! | X36: ='[3]CASA FORTE'!BS28 -> #DIV/0! | Y36: ='[3]CASA FORTE'!BV28 -> #DIV/0! | Z36: ='[3]CASA FORTE'!BY28 -> #DIV/0! | AA36: ='[3]CASA FORTE'!CB28 -> #DIV/0! | AB36: ='[3]CASA FORTE'!CE28 -> #DIV/0! | AC36: ='[3]CASA FORTE'!B31 -> 3 | AD36: ='[3]CASA FORTE'!B32 -> 2 | AE36: ='[3]CASA FORTE'!B33 -> 0 | AF36: ='[3]CASA FORTE'!B34 -> 0 | AG36: ='[3]CASA FORTE'!B35 -> 3 | AH36: ='[3]CASA FORTE'!$B$37 -> 14 | AI36: ='[3]CASA FORTE'!$B$38 -> 55263
A37: III | B37: PARNAMIRIM | C37: =[3]PARNAMIRIM!H30 -> 149.6 | D37: =[3]PARNAMIRIM!K30 -> 179.78571 | E37: =[3]PARNAMIRIM!N30 -> 145.4 | F37: =[3]PARNAMIRIM!Q30 -> 148.06667 | G37: =[3]PARNAMIRIM!T30 -> 179.25 | H37: =[3]PARNAMIRIM!W30 -> 132.28571 | I37: =[3]PARNAMIRIM!Z30 -> 141.91667 | J37: =[3]PARNAMIRIM!AC30 -> 186.41667 | K37: =[3]PARNAMIRIM!AF30 -> 56.133333 | L37: =[3]PARNAMIRIM!AI30 -> 133.30769 | M37: =[3]PARNAMIRIM!AL30 -> 261.66667 | N37: =[3]PARNAMIRIM!AO30 -> 144.57143 | O37: =[3]PARNAMIRIM!AR30 -> 124 | P37: =[3]PARNAMIRIM!AU30 -> 193.6 | Q37: =[3]PARNAMIRIM!AX30 -> 345.07143 | R37: =[3]PARNAMIRIM!BA30 -> 115 | S37: =[3]PARNAMIRIM!BD30 -> 123.76923 | T37: =[3]PARNAMIRIM!BG30 -> 82.1 | U37: =[3]PARNAMIRIM!BJ30 -> 155.8 | V37: =[3]PARNAMIRIM!BM30 -> #DIV/0! | W37: =[3]PARNAMIRIM!BP30 -> #DIV/0! | X37: =[3]PARNAMIRIM!BS30 -> #DIV/0! | Y37: =[3]PARNAMIRIM!BV30 -> #DIV/0! | Z37: =[3]PARNAMIRIM!BY30 -> #DIV/0! | AA37: =[3]PARNAMIRIM!CB30 -> #DIV/0! | AB37: =[3]PARNAMIRIM!CE30 -> #DIV/0! | AC37: =[3]PARNAMIRIM!B33 -> 33 | AD37: =[3]PARNAMIRIM!B34 -> 14 | AE37: =[3]PARNAMIRIM!B35 -> 0 | AF37: =[3]PARNAMIRIM!B36 -> 0 | AG37: =[3]PARNAMIRIM!B37 -> 20 | AH37: =[3]PARNAMIRIM!$B$39 -> 16 | AI37: =[3]PARNAMIRIM!$B$40 -> 40699
A38: III | B38: SANTANA | C38: =[3]SANTANA!H23 -> 311.625 | D38: =[3]SANTANA!K23 -> 273.55556 | E38: =[3]SANTANA!N23 -> 366.2 | F38: =[3]SANTANA!Q23 -> 660.66667 | G38: =[3]SANTANA!T23 -> 493.22222 | H38: =[3]SANTANA!W23 -> 533.22222 | I38: =[3]SANTANA!Z23 -> 408.77778 | J38: =[3]SANTANA!AC23 -> 225.875 | K38: =[3]SANTANA!AF23 -> 170.77778 | L38: =[3]SANTANA!AI23 -> 321.22222 | M38: =[3]SANTANA!AL23 -> 334.22222 | N38: =[3]SANTANA!AO23 -> 315.55556 | O38: =[3]SANTANA!AR23 -> 235 | P38: =[3]SANTANA!AU23 -> 173.44444 | Q38: =[3]SANTANA!AX23 -> 395.33333 | R38: =[3]SANTANA!BA23 -> 214.25 | S38: =[3]SANTANA!BD23 -> 229.875 | T38: =[3]SANTANA!BG23 -> 343.375 | U38: =[3]SANTANA!BJ23 -> 360.88889 | V38: =[3]SANTANA!BM23 -> #DIV/0! | W38: =[3]SANTANA!BP23 -> #DIV/0! | X38: =[3]SANTANA!BS23 -> #DIV/0! | Y38: =[3]SANTANA!BV23 -> #DIV/0! | Z38: =[3]SANTANA!BY23 -> #DIV/0! | AA38: =[3]SANTANA!CB23 -> #DIV/0! | AB38: =[3]SANTANA!CE23 -> #DIV/0! | AC38: =[3]SANTANA!B26 -> 0 | AD38: =[3]SANTANA!B27 -> 9 | AE38: =[3]SANTANA!B28 -> 0 | AF38: =[3]SANTANA!B29 -> 0 | AG38: =[3]SANTANA!B30 -> 1 | AH38: =[3]SANTANA!$B$32 -> 9 | AI38: =[3]SANTANA!$B$33 -> 54514
A39: III | B39: POÇO | C39: ='[3]POÇO DA PANELA'!H32 -> 181.94444 | D39: ='[3]POÇO DA PANELA'!K32 -> 240.94444 | E39: ='[3]POÇO DA PANELA'!N32 -> 250.72222 | F39: ='[3]POÇO DA PANELA'!Q32 -> 274.11765 | G39: ='[3]POÇO DA PANELA'!T32 -> 210.17647 | H39: ='[3]POÇO DA PANELA'!W32 -> 266.375 | I39: ='[3]POÇO DA PANELA'!Z32 -> 190.70588 | J39: ='[3]POÇO DA PANELA'!AC32 -> 260.5625 | K39: ='[3]POÇO DA PANELA'!AF32 -> 229.14286 | L39: ='[3]POÇO DA PANELA'!AI32 -> 271.5 | M39: ='[3]POÇO DA PANELA'!AL32 -> 306.55556 | N39: ='[3]POÇO DA PANELA'!AO32 -> 193.83333 | O39: ='[3]POÇO DA PANELA'!AR32 -> 222.16667 | P39: ='[3]POÇO DA PANELA'!AU32 -> 310.61111 | Q39: ='[3]POÇO DA PANELA'!AX32 -> 281.11765 | R39: ='[3]POÇO DA PANELA'!BA32 -> 174.83333 | S39: ='[3]POÇO DA PANELA'!BD32 -> 189.33333 | T39: ='[3]POÇO DA PANELA'!BG32 -> 210.4375 | U39: ='[3]POÇO DA PANELA'!BJ32 -> 189.70588 | V39: ='[3]POÇO DA PANELA'!BM32 -> #DIV/0! | W39: ='[3]POÇO DA PANELA'!BP32 -> #DIV/0! | X39: ='[3]POÇO DA PANELA'!BS32 -> #DIV/0! | Y39: ='[3]POÇO DA PANELA'!BV32 -> #DIV/0! | Z39: ='[3]POÇO DA PANELA'!BY32 -> #DIV/0! | AA39: ='[3]POÇO DA PANELA'!CB32 -> #DIV/0! | AB39: ='[3]POÇO DA PANELA'!CE32 -> #DIV/0! | AC39: ='[3]POÇO DA PANELA'!B36 -> 7 | AD39: ='[3]POÇO DA PANELA'!B37 -> 3 | AE39: ='[3]POÇO DA PANELA'!B38 -> 0 | AF39: ='[3]POÇO DA PANELA'!B39 -> 0 | AG39: ='[3]POÇO DA PANELA'!B40 -> 2 | AH39: ='[3]POÇO DA PANELA'!$B$42 -> 18 | AI39: ='[3]POÇO DA PANELA'!$B$43 -> 76106
A40: III | B40: SITIO DOS PINTOS | C40: ='[3]SITIO DOS PINTOS'!H40 -> 185 | D40: ='[3]SITIO DOS PINTOS'!K40 -> 128.65385 | E40: ='[3]SITIO DOS PINTOS'!N40 -> 319.34615 | F40: ='[3]SITIO DOS PINTOS'!Q40 -> 249.73077 | G40: ='[3]SITIO DOS PINTOS'!T40 -> 159.84615 | H40: ='[3]SITIO DOS PINTOS'!W40 -> 254.88462 | I40: ='[3]SITIO DOS PINTOS'!Z40 -> 134.07692 | J40: ='[3]SITIO DOS PINTOS'!AC40 -> 148.75 | K40: ='[3]SITIO DOS PINTOS'!AF40 -> 109.5 | L40: ='[3]SITIO DOS PINTOS'!AI40 -> 203.61538 | M40: ='[3]SITIO DOS PINTOS'!AL40 -> 160.88462 | N40: ='[3]SITIO DOS PINTOS'!AO40 -> 98.230769 | O40: ='[3]SITIO DOS PINTOS'!AR40 -> 133.88462 | P40: ='[3]SITIO DOS PINTOS'!AU40 -> 184.34615 | Q40: ='[3]SITIO DOS PINTOS'!AX40 -> 104.56 | R40: ='[3]SITIO DOS PINTOS'!BA40 -> 103.17391 | S40: ='[3]SITIO DOS PINTOS'!BD40 -> 124.11538 | T40: ='[3]SITIO DOS PINTOS'!BG40 -> 97.12 | U40: ='[3]SITIO DOS PINTOS'!BJ40 -> 99.28 | V40: ='[3]SITIO DOS PINTOS'!BM40 -> #DIV/0! | W40: ='[3]SITIO DOS PINTOS'!BP40 -> #DIV/0! | X40: ='[3]SITIO DOS PINTOS'!BS40 -> #DIV/0! | Y40: ='[3]SITIO DOS PINTOS'!BV40 -> #DIV/0! | Z40: ='[3]SITIO DOS PINTOS'!BY40 -> #DIV/0! | AA40: ='[3]SITIO DOS PINTOS'!CB40 -> #DIV/0! | AB40: ='[3]SITIO DOS PINTOS'!CE40 -> #DIV/0! | AC40: ='[3]SITIO DOS PINTOS'!B43 -> 2 | AD40: ='[3]SITIO DOS PINTOS'!B44 -> 0 | AE40: ='[3]SITIO DOS PINTOS'!B45 -> 0 | AF40: ='[3]SITIO DOS PINTOS'!B46 -> 0 | AG40: ='[3]SITIO DOS PINTOS'!B47 -> 2 | AH40: ='[3]SITIO DOS PINTOS'!$B$49 -> 26 | AI40: ='[3]SITIO DOS PINTOS'!$B$50 -> 77066
...

Sheet TABELA DINÂMICA
A3: Rótulos de Linha | B3: Média de CICLO 1 | C3: Média de CICLO 2 | D3: Média de CICLO 3 | E3: Média de CICLO 4 | F3: Média de CICLO 5 | G3: Média de CICLO 6 | H3: Média de CICLO 7 | I3: Média de CICLO 8 | J3: Média de CICLO 9 | K3: Média de CICLO 10 | L3: Média de CICLO 11 | M3: Média de CICLO 12 | N3: Média de CICLO 13
A4: I | B4: 236.09511 | C4: 206.3776 | D4: 187.12097 | E4: 177.80286 | F4: 144.07533 | G4: 187.13978 | H4: 157.84584 | I4: 178.53892 | J4: 240.99519 | K4: 203.91601 | L4: 185.77238 | M4: 214.59317 | N4: 262.40216
A5: II | B5: 258.42282 | C5: 207.06826 | D5: 178.16449 | E5: 267.00948 | F5: 211.69186 | G5: 288.34016 | H5: 248.04005 | I5: 230.96748 | J5: 211.95946 | K5: 212.16161 | L5: 232.34943 | M5: 212.21475 | N5: 303.10872
A6: III | B6: 282.5074 | C6: 208.99003 | D6: 183.43507 | E6: 229.61542 | F6: 270.71324 | G6: 244.96571 | H6: 201.43284 | I6: 201.32362 | J6: 196.82138 | K6: 185.43918 | L6: 160.79587 | M6: 123.1432 | N6: 203.38291
A7: IV | B7: 200.14231 | C7: 196.78933 | D7: 236.08496 | E7: 263.30301 | F7: 180.91473 | G7: 199.73764 | H7: 210.19409 | I7: 186.32582 | J7: 194.97231 | K7: 184.08234 | L7: 190.96041 | M7: 132.27088 | N7: 239.2939
A8: V | B8: 214.56882 | C8: 157.9137 | D8: 137.06468 | E8: 236.42345 | F8: 179.92943 | G8: 201.85801 | H8: 173.67667 | I8: 179.19232 | J8: 176.32919 | K8: 159.20886 | L8: 215.83087 | M8: 170.41984 | N8: 323.38981
A9: VI | B9: 227.44344 | C9: 247.48723 | D9: 173.9238 | E9: 268.65518 | F9: 254.09095 | G9: 209.90314 | H9: 265.01733 | I9: 233.85909 | J9: 174.14207 | K9: 243.24367 | L9: 250.98374 | M9: 214.66786 | N9: 326.46675
A10: VII | B10: 151.8166 | C10: 222.62621 | D10: 157.08173 | E10: 218.66502 | F10: 198.93176 | G10: 212.78548 | H10: 164.12335 | I10: 146.8105 | J10: 167.33727 | K10: 199.90296 | L10: 166.86848 | M10: 156.03849 | N10: 256.60808
A11: VIII | B11: 222.46916 | C11: 304.88643 | D11: 198.05737 | E11: 270.39447 | F11: 208.32303 | G11: 248.85536 | H11: 229.4567 | I11: 218.98728 | J11: 271.66061 | K11: 216.22152 | L11: 246.00067 | M11: 178.97639 | N11: 311.90331
A12: Total Geral | B12: 231.65296 | C12: 216.02797 | D12: 181.31383 | E12: 239.39267 | F12: 209.03341 | G12: 232.85736 | H12: 205.80163 | I12: 197.89979 | J12: 205.88271 | K12: 199.53638 | L12: 201.13686 | M12: 174.08763 | N12: 270.53376

Sheet Plan1
